# Generated by Django 3.1.3 on 2020-12-28 15:28

import django.contrib.auth.password_validation
import django.contrib.auth.validators
from django.db import migrations, models


class Migration(migrations.Migration):

    dependencies = [
        ('UserAuth', '0005_auto_20201228_1023'),
    ]

    operations = [
        migrations.AlterField(
            model_name='user',
            name='email',
            field=models.EmailField(default='', max_length=256, primary_key=True, serialize=False, unique=True),
        ),
        migrations.AlterField(
            model_name='user',
            name='first_name',
            field=models.CharField(default=None, max_length=200, null=True),
        ),
        migrations.AlterField(
            model_name='user',
            name='last_name',
            field=models.CharField(default=None, max_length=200, null=True),
        ),
        migrations.AlterField(
            model_name='user',
            name='password',
            field=models.CharField(default=None, max_length=30, null=True, validators=[django.contrib.auth.password_validation.MinimumLengthValidator, django.contrib.auth.password_validation.UserAttributeSimilarityValidator, django.contrib.auth.password_validation.CommonPasswordValidator, django.contrib.auth.password_validation.NumericPasswordValidator]),
        ),
        migrations.AlterField(
            model_name='user',
            name='username',
            field=models.CharField(default=None, error_messages={'unique': 'A User with that user name already exists.'}, max_length=128, null=True, unique=True, validators=[django.contrib.auth.validators.UnicodeUsernameValidator()]),
        ),
    ]
